Workbook
Name IRR: Gegevens!$I$36
Name Levensduur: Gegevens!$E$18
Name TVT: Gegevens!$D$36

Sheet Gegevens
B2: Berekening terugverdientermijn (TVT) en IRR
B4: versie: | C4: vs. 3.0
B5: Korte handleiding
B7: U vult volgende cellen in (met lichtgele achtergrond). De andere cellen zijn niet te wijzigen!
B8: - De blauwe cijfers in de cellen E12 tem E22 met de projectgegevens; met uitzondering van cel E14 (= % thematische aftrek, die berekend wordt op basis van de cellen E12 en E13) Let op ! Financiële waarden in 1.000 euro!
B9: - in cel E22 aangeven of de jaarlijkse besparingen identiek zijn voor elk jaar gedurende de levensduur. Indien niet, dan vult u in rij 27 gedurende de levensduur de effectieve jaarlijkse besparing in voor het betreffende jaar.
B12: In te vullen projectgegevens
D13: jaar van de investeringen
D14: grootte onderneming
D15: thematische aftrek | E15: =IF(OR(E13="",E14=""),"",IF(AND(E13=2025,E14="geen KO"),0.3,0.4))
D16: Investering | E16: 100 | F16: k€
D17: Installatiekosten | E17: 0 | F17: k€
D18: Levensduur | E18: 10 | F18: jaar
D19: Restwaarde bij einde levensduur | E19: 0 | F19: k€
D20: Afschrijvingstermijn | E20: 5 | F20: jaar
D21: Vennootschapsbelasting | E21: 0.25 | G21: =IF(E21<>0.25,"Opgepast ! Aangepaste vennootschapsbelasting !","")
D22: Netto besparing jaar 1 | E22: 20 | F22: k€
D23: netto besparingen elk jaar identiek? | E23: ja | F23: =IF(E23="nee","(*)","")
B24: =IF(E23="ja","","(*) Indien de netto-besparingen van jaar tot jaar verschillen: vul in rij 26 de correcte netto besparingen gedurende de levensduur in voor de jaren 2 tem " & Levensduur & " (vakjes met gele achtergrond).")
F26: Jaar
F27: 1 | G27: =F27+1 -> 2 | H27: =G27+1 -> 3 | I27: =H27+1 -> 4 | J27: =I27+1 -> 5 | K27: =J27+1 -> 6 | L27: =K27+1 -> 7 | M27: =L27+1 -> 8 | N27: =M27+1 -> 9 | ... AD27: =AC27+1 -> 25
C28: Netto besparing per jaar over de levensduur (k€) | F28: =$E$22 -> 20 | G28: =IF($E$23="ja",IF($E$18+1-G27>0,$E$22,0),IF($E$18+1-G27>0,"invullen!",0)) -> 20 | H28: =IF($E$23="ja",IF($E$18+1-H27>0,$E$22,0),IF($E$18+1-H27>0,"invullen!",0)) -> 20 | I28: =IF($E$23="ja",IF($E$18+1-I27>0,$E$22,0),IF($E$18+1-I27>0,"invullen!",0)) -> 20 | J28: =IF($E$23="ja",IF($E$18+1-J27>0,$E$22,0),IF($E$18+1-J27>0,"invullen!",0)) -> 20 | K28: =IF($E$23="ja",IF($E$18+1-K27>0,$E$22,0),IF($E$18+1-K27>0,"invullen!",0)) -> 20 | L28: =IF($E$23="ja",IF($E$18+1-L27>0,$E$22,0),IF($E$18+1-L27>0,"invullen!",0)) -> 20 | M28: =IF($E$23="ja",IF($E$18+1-M27>0,$E$22,0),IF($E$18+1-M27>0,"invullen!",0)) -> 20 | N28: =IF($E$23="ja",IF($E$18+1-N27>0,$E$22,0),IF($E$18+1-N27>0,"invullen!",0)) -> 20 | ... AD28: =IF($E$23="ja",IF($E$18+1-AD27>0,$E$22,0),IF($E$18+1-AD27>0,"invullen!",0)) -> 0
B33: Resultaat van TVT-berekening | G33: Resultaat van IRR-berekening
C36: TVT na belastingen: | D36: =IF($E$22=0,"",IF($G$28="invullen!","",IF($E$22<0,"Geen besparing!",'TVT-berekening'!L9))) -> meer dan 3 jaar | H36: IRR na belastingen: | I36: =IF($E$22=0,"",IF($G$28="invullen!","",IF($E$22<0,"Geen besparing!",'IRR-berekening'!M9))) -> 0.12725251
B40: Conclusie: | C40: =IF(E15="","Vul de gegevens in voor de berekening van thematische aftrek!",IF(OR(E16=0,E18=0,E20=0),"Vul alle nodige investeringsgegevens in!",IF($E$22<=0,"Vul de besparingen correct in ! Besparingen moeten groter zijn dan 0 !",IF($I$36="","",IF(TVT="minder dan 3 jaar","Geen verhoogde thematische aftrek van toepassing",IF(IRR>0.13,"Verhoogde thematische aftrek enkel van toepassing voor kleine ondernemingen","Verhoogde thematische aftrek van toepassing voor alle ondernemingen")))))) -> Vul de gegevens in voor de berekening van thematische aftrek!
B41: =IF(C40="Vul alle nodige gegevens in!","",IF(IRR="","","Reden:")) -> Reden: | C41: =IF(C40="Vul alle nodige gegevens in!","",IF(IRR="","",IF($I$36="","",IF(TVT="minder dan 3 jaar","De TVT moet minstens 3 jaar zijn",IF(IRR>0.13,"De IRR mag maximaal 13% zijn voor ondernemingen die niet klein zijn","")))))

Sheet TVT-berekening
A1: Berekening terugverdientermijn (TVT) van de investeringen
A3: projectgegevens | H3: Resultaat van TVT-berekening
C5: =Gegevens!D16 -> Investering | D5: =Gegevens!E16 -> 100 | E5: =Gegevens!F16 -> k€
C6: =Gegevens!D17 -> Installatiekosten | D6: =Gegevens!E17 -> 0 | E6: =Gegevens!F17 -> k€ | I6: TVT vóór belastingen: | L6: =E28 -> meer dan 3 jaar
C7: =Gegevens!D18 -> Levensduur | D7: =Gegevens!E18 -> 10 | E7: =Gegevens!F18 -> jaar
C8: =Gegevens!D22 -> Netto besparing jaar 1 | D8: =Gegevens!E22 -> 20 | E8: =Gegevens!F22 -> k€
C9: =Gegevens!D19 -> Restwaarde bij einde levensduur | D9: =Gegevens!E19 -> 0 | E9: =Gegevens!F19 -> k€ | I9: TVT na belastingen: | L9: =E46 -> meer dan 3 jaar
C10: =Gegevens!D20 -> Afschrijvingstermijn | D10: =Gegevens!E20 -> 5 | E10: =Gegevens!F20 -> jaar
C11: Thematische aftrek | D11: =Gegevens!E15
C12: =Gegevens!D21 -> Vennootschapsbelasting | D12: =Gegevens!E21 -> 0.25
A15: Hieronder wordt de wijze van berekening van de IRR vóór resp. na belastingen weergegeven.
A17: TVT berekening vóór belasting
E19: Jaar
E20: 0 | F20: 1 | G20: 2 | H20: 3 | I20: 4
B21: Investering | E21: =-(D5) -> -100
B22: Restwaarde bij einde levensduur | F22: =IF($D$7=F20,$D$9,0) -> 0 | G22: =IF($D$7=G20,$D$9,0) -> 0 | H22: =IF($D$7=H20,$D$9,0) -> 0 | I22: =IF($D$7=I20,$D$9,0) -> 0
B23: Installatiekosten | E23: =-D6 -> 0
B24: Netto besparing per jaar over de levensduur | F24: ='IRR-berekening'!F24 -> 20 | G24: ='IRR-berekening'!G24 -> 20 | H24: ='IRR-berekening'!H24 -> 20 | I24: ='IRR-berekening'!I24 -> 20
B25: Totale kasstroom | E25: =SUM(E21:E24) -> -100 | F25: =SUM(F21:F24) -> 20 | G25: =SUM(G21:G24) -> 20 | H25: =SUM(H21:H24) -> 20 | I25: =SUM(I21:I24) -> 20
B26: Cumulatieve kasstroom | E26: =E25 -> -100 | F26: =SUM($E25:F25) -> -80 | G26: =SUM($E25:G25) -> -60 | H26: =SUM($E25:H25) -> -40 | I26: =SUM($E25:I25) -> -20
B28: Berekening TVT voor belastingen: | E28: =IF(D7=0,"",IF(H26<0,"meer dan 3 jaar",IF(H26>0,"minder dan 3 jaar","exact 3 jaar"))) -> meer dan 3 jaar
A31: TVT berekening na belasting
E33: Jaar
E34: 0 | F34: 1 | G34: 2 | H34: 3 | I34: 4
B35: Investering | E35: =-(D5) -> -100
B36: Restwaarde bij einde levensduur | F36: =IF($D$7=F34,$D$9,0) -> 0 | G36: =IF($D$7=G34,$D$9,0) -> 0 | H36: =IF($D$7=H34,$D$9,0) -> 0 | I36: =IF($D$7=I34,$D$9,0) -> 0
B37: Installatiekosten | E37: =-D6 -> 0
B38: Netto besparing per jaar over de levensduur | F38: =F24 -> 20 | G38: =G24 -> 20 | H38: =H24 -> 20 | I38: =I24 -> 20
B39: Belasting op opbrengsten | E39: =-E37*$D$12 -> 0 | F39: =-F38*$D$12 -> -5 | G39: =-G38*$D$12 -> -5 | H39: =-H38*$D$12 -> -5 | I39: =-I38*$D$12 -> -5
D40: Thematische aftrek | E40: =IF($D$11="",0,$D$11*$D$5*$D$12) -> 0
B41: Afschrijving per jaar | F41: =IF($D$10+1-F$34>0,($D$5/$D$10),0) -> 20 | G41: =IF($D$10+1-G$34>0,($D$5/$D$10),0) -> 20 | H41: =IF($D$10+1-H$34>0,($D$5/$D$10),0) -> 20 | I41: =IF($D$10+1-I$34>0,($D$5/$D$10),0) -> 20
B42: Verminderde belasting door afschrijving | F42: =IF(F$41>0,F41*$D$12,0) -> 5 | G42: =IF(G$41>0,G41*$D$12,0) -> 5 | H42: =IF(H$41>0,H41*$D$12,0) -> 5 | I42: =IF(I$41>0,I41*$D$12,0) -> 5
B43: Totale kasstroom | E43: =SUM(E35:E42) -> -100 | F43: =SUM(F35:F42)-F41 -> 20 | G43: =SUM(G35:G42)-G41 -> 20 | H43: =SUM(H35:H42)-H41 -> 20 | I43: =SUM(I35:I42)-I41 -> 20
B44: Cumulatieve kasstroom | E44: =E43 -> -100 | F44: =SUM($E43:F43) -> -80 | G44: =SUM($E43:G43) -> -60 | H44: =SUM($E43:H43) -> -40 | I44: =SUM($E43:I43) -> -20
B46: Berekening TVT na belastingen: | E46: =IF(D7=0,"",IF(H44<0,"meer dan 3 jaar",IF(H44>0,"minder dan 3 jaar","exact 3 jaar"))) -> meer dan 3 jaar
C47: 0

Sheet IRR-berekening
A1: Berekening IRR van de investeringen
A3: projectgegevens | H3: Resultaat van IRR-berekening
C5: =Gegevens!D16 -> Investering | D5: =Gegevens!E16 -> 100 | E5: =Gegevens!F16 -> k€
C6: =Gegevens!D17 -> Installatiekosten | D6: =Gegevens!E17 -> 0 | E6: =Gegevens!F17 -> k€ | L6: IRR vóór belastingen: | M6: =C28 -> 0.15098414
C7: =Gegevens!D18 -> Levensduur | D7: =Gegevens!E18 -> 10 | E7: =Gegevens!F18 -> jaar
C8: =Gegevens!D22 -> Netto besparing jaar 1 | D8: =Gegevens!E22 -> 20 | E8: =Gegevens!F22 -> k€
C9: =Gegevens!D19 -> Restwaarde bij einde levensduur | D9: =Gegevens!E19 -> 0 | E9: =Gegevens!F19 -> k€ | L9: IRR na belastingen: | M9: =C64 -> 0.12725251
C10: =Gegevens!D20 -> Afschrijvingstermijn | D10: =Gegevens!E20 -> 5 | E10: =Gegevens!F20 -> jaar
C11: Thematische aftrek | D11: =Gegevens!E15
C12: =Gegevens!D21 -> Vennootschapsbelasting | D12: =Gegevens!E21 -> 0.25
A15: Hieronder wordt de wijze van berekening van de IRR vóór resp. na belastingen weergegeven.
A17: IRR berekening vóór belasting
E19: Jaar
E20: 0 | F20: =E20+1 -> 1 | G20: =F20+1 -> 2 | H20: =G20+1 -> 3 | I20: =H20+1 -> 4 | J20: =I20+1 -> 5 | K20: =J20+1 -> 6 | L20: =K20+1 -> 7 | M20: =L20+1 -> 8 | ... AD20: =AC20+1 -> 25
B21: Investering | E21: =-(D5) -> -100
B22: Restwaarde bij einde levensduur | F22: =IF($D$7=F20,$D$9,0) -> 0 | G22: =IF($D$7=G20,$D$9,0) -> 0 | H22: =IF($D$7=H20,$D$9,0) -> 0 | I22: =IF($D$7=I20,$D$9,0) -> 0 | J22: =IF($D$7=J20,$D$9,0) -> 0 | K22: =IF($D$7=K20,$D$9,0) -> 0 | L22: =IF($D$7=L20,$D$9,0) -> 0 | M22: =IF($D$7=M20,$D$9,0) -> 0 | ... AD22: =IF($D$7=AD20,$D$9,0) -> 0
B23: Installatiekosten | E23: =-D6 -> 0
B24: Netto besparing per jaar over de levensduur | F24: =Gegevens!F28 -> 20 | G24: =Gegevens!G28 -> 20 | H24: =Gegevens!H28 -> 20 | I24: =Gegevens!I28 -> 20 | J24: =Gegevens!J28 -> 20 | K24: =Gegevens!K28 -> 20 | L24: =Gegevens!L28 -> 20 | M24: =Gegevens!M28 -> 20 | ... AD24: =Gegevens!AD28 -> 0
B25: Totale kasstroom | E25: =SUM(E21:E24) -> -100 | F25: =SUM(F21:F24) -> 20 | G25: =SUM(G21:G24) -> 20 | H25: =SUM(H21:H24) -> 20 | I25: =SUM(I21:I24) -> 20 | J25: =SUM(J21:J24) -> 20 | K25: =SUM(K21:K24) -> 20 | L25: =SUM(L21:L24) -> 20 | ... AD25: =SUM(AD21:AD24) -> 0
A27: De IRR wordt berekend m.b.v. een formule (iteratie) en geeft
A28: volgend resultaat: | B28: IRR : | C28: =IF(D7=0,"",IRR(E25:AD25)) -> 0.15098414
C29: 0
A30: Dit kan zichtbaar gemaakt worden door bij verschillende rentevoeten de NCW te berekenen en te kijken bij welke rentevoet de NCW = 0 wordt
C32: rentevoet | D32: NCW in het jaar van investeren | E32: Jaar
E33: 0 | F33: =E33+1 -> 1 | G33: =F33+1 -> 2 | H33: =G33+1 -> 3 | I33: =H33+1 -> 4 | J33: =I33+1 -> 5 | K33: =J33+1 -> 6 | L33: =K33+1 -> 7 | M33: =L33+1 -> 8 | ... AD33: =AC33+1 -> 25
C34: 0 | D34: =SUM(E34:Y34) -> 100 | E34: =SUM(E$21:E$24) -> -100 | F34: =SUM(F$21:F$24)/POWER(1+$C34/100,F$20) -> 20 | G34: =SUM(G$21:G$24)/POWER(1+$C34/100,G$20) -> 20 | H34: =SUM(H$21:H$24)/POWER(1+$C34/100,H$20) -> 20 | I34: =SUM(I$21:I$24)/POWER(1+$C34/100,I$20) -> 20 | J34: =SUM(J$21:J$24)/POWER(1+$C34/100,J$20) -> 20 | K34: =SUM(K$21:K$24)/POWER(1+$C34/100,K$20) -> 20 | L34: =SUM(L$21:L$24)/POWER(1+$C34/100,L$20) -> 20 | M34: =SUM(M$21:M$24)/POWER(1+$C34/100,M$20) -> 20 | ... AD34: =SUM(AD$21:AD$24)/POWER(1+$C34/100,AD$20) -> 0
C35: =C34+5 -> 5 | D35: =SUM(E35:Y35) -> 54.434699 | E35: =SUM(E$21:E$24) -> -100 | F35: =SUM(F$21:F$24)/POWER(1+$C35/100,F$20) -> 19.047619 | G35: =SUM(G$21:G$24)/POWER(1+$C35/100,G$20) -> 18.14059 | H35: =SUM(H$21:H$24)/POWER(1+$C35/100,H$20) -> 17.276752 | I35: =SUM(I$21:I$24)/POWER(1+$C35/100,I$20) -> 16.454049 | J35: =SUM(J$21:J$24)/POWER(1+$C35/100,J$20) -> 15.670523 | K35: =SUM(K$21:K$24)/POWER(1+$C35/100,K$20) -> 14.924308 | L35: =SUM(L$21:L$24)/POWER(1+$C35/100,L$20) -> 14.213627 | M35: =SUM(M$21:M$24)/POWER(1+$C35/100,M$20) -> 13.536787 | ... AD35: =SUM(AD$21:AD$24)/POWER(1+$C35/100,AD$20) -> 0
C36: =C35+5 -> 10 | D36: =SUM(E36:Y36) -> 22.891342 | E36: =SUM(E$21:E$24) -> -100 | F36: =SUM(F$21:F$24)/POWER(1+$C36/100,F$20) -> 18.181818 | G36: =SUM(G$21:G$24)/POWER(1+$C36/100,G$20) -> 16.528926 | H36: =SUM(H$21:H$24)/POWER(1+$C36/100,H$20) -> 15.026296 | I36: =SUM(I$21:I$24)/POWER(1+$C36/100,I$20) -> 13.660269 | J36: =SUM(J$21:J$24)/POWER(1+$C36/100,J$20) -> 12.418426 | K36: =SUM(K$21:K$24)/POWER(1+$C36/100,K$20) -> 11.289479 | L36: =SUM(L$21:L$24)/POWER(1+$C36/100,L$20) -> 10.263162 | M36: =SUM(M$21:M$24)/POWER(1+$C36/100,M$20) -> 9.3301476 | ... AD36: =SUM(AD$21:AD$24)/POWER(1+$C36/100,AD$20) -> 0
C37: =C36+5 -> 15 | D37: =SUM(E37:Y37) -> 0.37537252 | E37: =SUM(E$21:E$24) -> -100 | F37: =SUM(F$21:F$24)/POWER(1+$C37/100,F$20) -> 17.391304 | G37: =SUM(G$21:G$24)/POWER(1+$C37/100,G$20) -> 15.122873 | H37: =SUM(H$21:H$24)/POWER(1+$C37/100,H$20) -> 13.150325 | I37: =SUM(I$21:I$24)/POWER(1+$C37/100,I$20) -> 11.435065 | J37: =SUM(J$21:J$24)/POWER(1+$C37/100,J$20) -> 9.9435347 | K37: =SUM(K$21:K$24)/POWER(1+$C37/100,K$20) -> 8.6465519 | L37: =SUM(L$21:L$24)/POWER(1+$C37/100,L$20) -> 7.5187408 | M37: =SUM(M$21:M$24)/POWER(1+$C37/100,M$20) -> 6.5380355 | ... AD37: =SUM(AD$21:AD$24)/POWER(1+$C37/100,AD$20) -> 0
C38: =C37+5 -> 20 | D38: =SUM(E38:Y38) -> -16.150558 | E38: =SUM(E$21:E$24) -> -100 | F38: =SUM(F$21:F$24)/POWER(1+$C38/100,F$20) -> 16.666667 | G38: =SUM(G$21:G$24)/POWER(1+$C38/100,G$20) -> 13.888889 | H38: =SUM(H$21:H$24)/POWER(1+$C38/100,H$20) -> 11.574074 | I38: =SUM(I$21:I$24)/POWER(1+$C38/100,I$20) -> 9.6450617 | J38: =SUM(J$21:J$24)/POWER(1+$C38/100,J$20) -> 8.0375514 | K38: =SUM(K$21:K$24)/POWER(1+$C38/100,K$20) -> 6.6979595 | L38: =SUM(L$21:L$24)/POWER(1+$C38/100,L$20) -> 5.5816329 | M38: =SUM(M$21:M$24)/POWER(1+$C38/100,M$20) -> 4.6513608 | ... AD38: =SUM(AD$21:AD$24)/POWER(1+$C38/100,AD$20) -> 0
C39: =C38+5 -> 25 | D39: =SUM(E39:Y39) -> -28.589935 | E39: =SUM(E$21:E$24) -> -100 | F39: =SUM(F$21:F$24)/POWER(1+$C39/100,F$20) -> 16 | G39: =SUM(G$21:G$24)/POWER(1+$C39/100,G$20) -> 12.8 | H39: =SUM(H$21:H$24)/POWER(1+$C39/100,H$20) -> 10.24 | I39: =SUM(I$21:I$24)/POWER(1+$C39/100,I$20) -> 8.192 | J39: =SUM(J$21:J$24)/POWER(1+$C39/100,J$20) -> 6.5536 | K39: =SUM(K$21:K$24)/POWER(1+$C39/100,K$20) -> 5.24288 | L39: =SUM(L$21:L$24)/POWER(1+$C39/100,L$20) -> 4.194304 | M39: =SUM(M$21:M$24)/POWER(1+$C39/100,M$20) -> 3.3554432 | ... AD39: =SUM(AD$21:AD$24)/POWER(1+$C39/100,AD$20) -> 0
C40: =C39+5 -> 30 | D40: =SUM(E40:Y40) -> -38.16921 | E40: =SUM(E$21:E$24) -> -100 | F40: =SUM(F$21:F$24)/POWER(1+$C40/100,F$20) -> 15.384615 | G40: =SUM(G$21:G$24)/POWER(1+$C40/100,G$20) -> 11.83432 | H40: =SUM(H$21:H$24)/POWER(1+$C40/100,H$20) -> 9.1033227 | I40: =SUM(I$21:I$24)/POWER(1+$C40/100,I$20) -> 7.0025559 | J40: =SUM(J$21:J$24)/POWER(1+$C40/100,J$20) -> 5.3865815 | K40: =SUM(K$21:K$24)/POWER(1+$C40/100,K$20) -> 4.1435242 | L40: =SUM(L$21:L$24)/POWER(1+$C40/100,L$20) -> 3.1873263 | M40: =SUM(M$21:M$24)/POWER(1+$C40/100,M$20) -> 2.4517895 | ... AD40: =SUM(AD$21:AD$24)/POWER(1+$C40/100,AD$20) -> 0
C41: =C40+5 -> 35 | D41: =SUM(E41:Y41) -> -45.699144 | E41: =SUM(E$21:E$24) -> -100 | F41: =SUM(F$21:F$24)/POWER(1+$C41/100,F$20) -> 14.814815 | G41: =SUM(G$21:G$24)/POWER(1+$C41/100,G$20) -> 10.973937 | H41: =SUM(H$21:H$24)/POWER(1+$C41/100,H$20) -> 8.1288421 | I41: =SUM(I$21:I$24)/POWER(1+$C41/100,I$20) -> 6.0213646 | J41: =SUM(J$21:J$24)/POWER(1+$C41/100,J$20) -> 4.46027 | K41: =SUM(K$21:K$24)/POWER(1+$C41/100,K$20) -> 3.3039037 | L41: =SUM(L$21:L$24)/POWER(1+$C41/100,L$20) -> 2.4473361 | M41: =SUM(M$21:M$24)/POWER(1+$C41/100,M$20) -> 1.8128416 | ... AD41: =SUM(AD$21:AD$24)/POWER(1+$C41/100,AD$20) -> 0
C42: =C41+5 -> 40 | D42: =SUM(E42:Y42) -> -51.728581 | E42: =SUM(E$21:E$24) -> -100 | F42: =SUM(F$21:F$24)/POWER(1+$C42/100,F$20) -> 14.285714 | G42: =SUM(G$21:G$24)/POWER(1+$C42/100,G$20) -> 10.204082 | H42: =SUM(H$21:H$24)/POWER(1+$C42/100,H$20) -> 7.2886297 | I42: =SUM(I$21:I$24)/POWER(1+$C42/100,I$20) -> 5.2061641 | J42: =SUM(J$21:J$24)/POWER(1+$C42/100,J$20) -> 3.7186886 | K42: =SUM(K$21:K$24)/POWER(1+$C42/100,K$20) -> 2.6562062 | L42: =SUM(L$21:L$24)/POWER(1+$C42/100,L$20) -> 1.8972901 | M42: =SUM(M$21:M$24)/POWER(1+$C42/100,M$20) -> 1.3552072 | ... AD42: =SUM(AD$21:AD$24)/POWER(1+$C42/100,AD$20) -> 0
C43: =C42+5 -> 45 | D43: =SUM(E43:Y43) -> -56.637332 | E43: =SUM(E$21:E$24) -> -100 | F43: =SUM(F$21:F$24)/POWER(1+$C43/100,F$20) -> 13.793103 | G43: =SUM(G$21:G$24)/POWER(1+$C43/100,G$20) -> 9.5124851 | H43: =SUM(H$21:H$24)/POWER(1+$C43/100,H$20) -> 6.5603346 | I43: =SUM(I$21:I$24)/POWER(1+$C43/100,I$20) -> 4.5243687 | J43: =SUM(J$21:J$24)/POWER(1+$C43/100,J$20) -> 3.1202543 | K43: =SUM(K$21:K$24)/POWER(1+$C43/100,K$20) -> 2.1518995 | L43: =SUM(L$21:L$24)/POWER(1+$C43/100,L$20) -> 1.4840686 | M43: =SUM(M$21:M$24)/POWER(1+$C43/100,M$20) -> 1.0234956 | ... AD43: =SUM(AD$21:AD$24)/POWER(1+$C43/100,AD$20) -> 0
C44: =C43+5 -> 50 | D44: =SUM(E44:Y44) -> -60.693661 | E44: =SUM(E$21:E$24) -> -100 | F44: =SUM(F$21:F$24)/POWER(1+$C44/100,F$20) -> 13.333333 | G44: =SUM(G$21:G$24)/POWER(1+$C44/100,G$20) -> 8.8888889 | H44: =SUM(H$21:H$24)/POWER(1+$C44/100,H$20) -> 5.9259259 | I44: =SUM(I$21:I$24)/POWER(1+$C44/100,I$20) -> 3.9506173 | J44: =SUM(J$21:J$24)/POWER(1+$C44/100,J$20) -> 2.6337449 | K44: =SUM(K$21:K$24)/POWER(1+$C44/100,K$20) -> 1.7558299 | L44: =SUM(L$21:L$24)/POWER(1+$C44/100,L$20) -> 1.1705533 | M44: =SUM(M$21:M$24)/POWER(1+$C44/100,M$20) -> 0.78036885 | ... AD44: =SUM(AD$21:AD$24)/POWER(1+$C44/100,AD$20) -> 0
C46: De rentevoet waarbij de netto contante waarde = 0 wordt, is de IRR van de investering vóór belastingen
A49: IRR berekening na belasting
E51: Jaar
E52: 0 | F52: =E52+1 -> 1 | G52: =F52+1 -> 2 | H52: =G52+1 -> 3 | I52: =H52+1 -> 4 | J52: =I52+1 -> 5 | K52: =J52+1 -> 6 | L52: =K52+1 -> 7 | M52: =L52+1 -> 8 | ... AD52: =AC52+1 -> 25
...

Sheet versiebeheer
A1: nr. | B1: versie | C1: Datum | D1: Omschrijving
A2: 1 | B2: ="vs. "& A2 &".0" -> vs. 1.0 | C2: 46161 | D2: versie obv sjabloon premie na audit
A3: 2 | B3: ="vs. "& A3 &".0" -> vs. 2.0 | C3: 46192 | D3: aanpassingen: - incl. thematische aftrek - exploitatieperiode uitgebreid tot 25 jaar - mogelijkheid tot besparingen verschillend jaar tot jaar
A4: 3 | B4: ="vs. "& A4 &".0" -> vs. 3.0 | C4: 46255 | D4: aanpassingen: - thematische aftrek = 30% voor niet KO voor investeringen 2025
